Workbook

Sheet Summary
A1: ECI AI PLATFORM BUILD – ESTIMATION SUMMARY
A3: Variables | F3: Team Allocation | L3: S.N. | Pre-Requisites (Client Responsibility)
A4: SNO | B4: Variables | C4: # | F4: SNO | G4: Role | H4: Allocation % | I4: Est. Days | L4: 1 | M4: Active Azure subscription with Contributor or Owner role at resource group level
A5: 1 | B5: FrontEnd | C5: No | F5: SNO | G5: Role | H5: Allocation % | I5: Est. Days | L5: 2 | M5: Microsoft 365 E3 (or higher) licenses for all service and user accounts
A6: 2 | B6: Backend | C6: Yes | F6: 1 | G6: Project Manager | H6: 25% | I6: =(('AI Agent Dev- Backend'!F67+DevOps!F28)/7)*0.25 | L6: 3 | M6: Copilot Studio license (standalone ~$200/tenant/mo or via M365 tier — confirm with client)
A7: 3 | B7: DevOps | C7: Yes | F7: 2 | G7: AI Architect / Lead | H7: 50% | I7: =(('AI Agent Dev- Backend'!F67+DevOps!F28)/7)*0.5 | L7: 4 | M7: Read/write SharePoint credentials and Graph API permissions for all source data
A8: 4 | B8: QA | C8: Yes | F8: 3 | G8: AI Engineer | H8: 100% | I8: =(('AI Agent Dev- Backend'!F67+DevOps!F28)/7)*1.0 | L8: 5 | M8: Microsoft Teams admin consent for custom Copilot Studio bot deployment
A9: 5 | B9: Mobile | C9: No | F9: 4 | G9: QA Engineer | H9: 50% | I9: =(('AI Agent Dev- Backend'!F67+DevOps!F28)/7)*0.5 | L9: 6 | M9: Azure AD user accounts provisioned for 10 POC users
A10: Activities | F10: 5 | G10: DevOps Engineer | H10: 25% | I10: =(('AI Agent Dev- Backend'!F67+DevOps!F28)/7)*0.25 | L10: 7 | M10: Identification of key stakeholders for workshops and UAT sign-off
A11: SNO | B11: Activities | D11: DevTime (hrs) | F11: 6 | G11: Data Engineer | H11: 50% | I11: =(('AI Agent Dev- Backend'!F67+DevOps!F28)/7)*0.5 | L11: 8 | M11: Access to all REST APIs and data sources listed in scope
A12: 1 | B12: FrontEnd | D12: 0 | L12: 9 | M12: Sample document corpus (50–100 files per use case) provided within 1 week of kickoff
A13: 2 | B13: Backend | D13: ='AI Agent Dev- Backend'!F67 | L13: 10 | M13: Agreed document template formats locked before ingestion begins
A14: 3 | B14: DevOps | D14: =DevOps!F28 | F14: Monthly Infra Cost (Est.) | H14: ='Infra Cost'!C37
L15: S.N. | Out of Scope
B16: Component | C16: Days | D16: Weeks | L16: 1 | M16: Data ingestion from sources outside the agreed list (non-approved data)
B17: FrontEnd | C17: 0 | D17: 0 | L17: 2 | M17: Automated real-time ingestion — only one-time + scheduled delta ingestion in scope
B18: Backend | C18: ='AI Agent Dev- Backend'!F67/7 | D18: ='AI Agent Dev- Backend'!F67/35 | L18: 3 | M18: Custom UI development outside Teams (no web portal or mobile app)
B19: DevOps | C19: =DevOps!F28/7 | D19: =DevOps!F28/35 | L19: 4 | M19: Building full CI/CD pipelines or advanced release automation
A20: Project Duration | D20: ='AI Agent Dev- Backend'!F67/35 | L20: 5 | M20: PowerPoint (.pptx) and image files as primary data source types
L21: 6 | M21: Long-term AI operations support beyond the 30-day stabilisation period
A22: Project Duration including Leaves & Holiday | L22: 7 | M22: Unstructured formats like audio and video not supported as data sources
B23: Leaves & Holiday | C23: 1 | D23: Weeks | L23: 8 | M23: Multi-language support beyond English + 1 additional language
C24: ='AI Agent Dev- Backend'!F67/35+C23 | D24: Weeks | L24: 9 | M24: Real-time external data feeds (market data, live APIs beyond what is listed)
A25: Note: With 2 AI Engineers, project can be completed within 8-10 weeks. | L25: 10 | M25: Any new features or requests not mentioned in scope (change request process applies)
L27: S.N. | Assumptions
L28: 1 | M28: Source files are PDF, Word, and Excel only — all other formats excluded unless specifically agreed
L29: 2 | M29: 50–100 historical files per use case will be provided within POC scope
L30: 3 | M30: AI response accuracy is estimated at 80–95% for structured queries. 100% accuracy is not guaranteed.
L31: 4 | M31: AI responses are advisory in nature — all outputs must be reviewed and validated by client before decisions.
L32: 5 | M32: Model accuracy is dependent on quality, consistency, and completeness of source files provided.
L33: 6 | M33: A single agreed-upon document template per use case will be confirmed and locked during Discovery & Design.
L34: 7 | M34: One-time ingestion plus scheduled delta sync; no real-time streaming ingestion.
L35: 8 | M35: 10 users will participate in UAT, each testing 50–100 queries across all 3 use cases.
L36: 9 | M36: Users must have existing SharePoint and Teams access to use the agent.
L37: 10 | M37: Prompt logs stored in Azure Monitor / Log Analytics with 90-day default retention.
L38: 11 | M38: Existing Azure landing zone and subscription will be leveraged — no new subscription required.
L39: 12 | M39: Client is responsible for all Azure/cloud licensing, infrastructure, and data usage costs.
... L42: 15 | M42: Data classification and labeling not required for the POC phase.
L44: S.N. | Risks
L45: 1 | M45: API restrictions: Permission or access issues may add significant effort — validate in Discovery.
...

Sheet AI Agent Dev- Backend
A1: ECI AI PLATFORM BUILD – AI AGENT DEVELOPMENT & INTEGRATION
A3: # | B3: Task / Phase | C3: Sub-task | D3: Dev Low (hrs) | E3: Dev High (hrs) | F3: Avg (hrs) | G3: Comments
A4: Phase 1: Discovery & Design | D4: =SUM(D5:D13) | E4: =SUM(E5:E13) | F4: =(D4+E4)/2
A5: 1 | C5: Project kickoff, scope alignment & stakeholder mapping | D5: 10 | E5: 14 | F5: =(D5+E5)/2 | G5: Workshops with business & tech leads
A6: 2 | C6: Existing system & data source review (APIs, DBs, file stores) | D6: 8 | E6: 12 | F6: =(D6+E6)/2 | G6: Audit current integrations & data quality
A7: 3 | C7: 50–100 document sample analysis (PDFs, Word, Excel) | D7: 8 | E7: 12 | F7: =(D7+E7)/2 | G7: Validate content types and metadata structure
A8: 4 | C8: Solution architecture finalization & sign-off | D8: 6 | E8: 8 | F8: =(D8+E8)/2 | G8: Private endpoint, cloud landing zone design
A9: 5 | C9: Technical design documentation (HLD + LLD) | D9: 12 | E9: 16 | F9: =(D9+E9)/2 | G9: Architecture & data flow diagrams
A10: 6 | C10: Prompt engineering design for all use cases | D10: 8 | E10: 12 | F10: =(D10+E10)/2 | G10: Use-case specific prompt templates
A11: 7 | C11: KPI metric & threshold definition | D11: 6 | E11: 10 | F11: =(D11+E11)/2 | G11: Accuracy, latency, relevance benchmarks
A12: 8 | C12: Data governance & compliance review | D12: 4 | E12: 6 | F12: =(D12+E12)/2 | G12: GDPR / data residency checks
A13: 9 | C13: Risk assessment & mitigation plan documentation | D13: 4 | E13: 6 | F13: =(D13+E13)/2 | G13: Risk register creation
A15: Phase 2: Data Ingestion & Processing Pipeline | D15: =SUM(D16:D24) | E15: =SUM(E16:E24) | F15: =(D15+E15)/2
A16: 10 | C16: Connector setup for source systems (REST API, SharePoint, SQL) | D16: 8 | E16: 12 | F16: =(D16+E16)/2 | G16: One-time ingestion pipeline per source
A17: 11 | C17: PDF/Word/Excel parsing, extraction & metadata tagging | D17: 10 | E17: 14 | F17: =(D17+E17)/2 | G17: Multi-format document processing
A18: 12 | C18: Intelligent chunking strategy & overlap configuration | D18: 6 | E18: 10 | F18: =(D18+E18)/2 | G18: Optimised for RAG retrieval accuracy
A19: 13 | C19: Azure OpenAI embedding integration (2 embedding models) | D19: 14 | E19: 18 | F19: =(D19+E19)/2 | G19: text-embedding-3-large + ada-002
A20: 14 | C20: One-time embedding generation for all source documents | D20: 12 | E20: 16 | F20: =(D20+E20)/2 | G20: Full corpus vectorisation
A21: 15 | C21: Azure AI Search schema design + hybrid search config | D21: 16 | E21: 22 | F21: =(D21+E21)/2 | G21: Vector + BM25 keyword hybrid index
A22: 16 | C22: Azure SQL metadata store design & population | D22: 6 | E22: 10 | F22: =(D22+E22)/2 | G22: Structured lookup tables
A23: 17 | C23: Data validation & ingestion QA | D23: 4 | E23: 6 | F23: =(D23+E23)/2 | G23: Spot-check retrieval quality
A24: 18 | C24: Automated re-ingestion trigger (delta updates) | D24: 6 | E24: 10 | F24: =(D24+E24)/2 | G24: Scheduled incremental sync
A26: Phase 3: AI Agent Development | D26: =SUM(D27:D38) | E26: =SUM(E27:E38) | F26: =(D26+E26)/2
A27: 19 | C27: Use Case 1: Document Q&A – prompt engineering & RAG pipeline | D27: 10 | E27: 14 | F27: =(D27+E27)/2 | G27: Natural language Q&A over enterprise docs
A28: 20 | C28: Use Case 1: Contextual answer generation with citation | D28: 10 | E28: 14 | F28: =(D28+E28)/2 | G28: Source attribution for every response
A29: 21 | C29: Use Case 1: Adaptive Card trigger & response formatting (Teams) | D29: 6 | E29: 8 | F29: =(D29+E29)/2 | G29: Trigger via Teams; output as rich card
A30: 22 | C30: Use Case 2: Intelligent Report Summarisation – RAG pipeline | D30: 10 | E30: 14 | F30: =(D30+E30)/2 | G30: Auto-summarise lengthy reports
A31: 23 | C31: Use Case 2: Multi-document synthesis & comparison logic | D31: 8 | E31: 12 | F31: =(D31+E31)/2 | G31: Cross-document insights
A32: 24 | C32: Use Case 2: Structured summary output & export (Word/PDF) | D32: 6 | E32: 8 | F32: =(D32+E32)/2 | G32: Formatted downloadable summaries
A33: 25 | C33: Use Case 3: Anomaly & Insight Detection from structured data | D33: 8 | E33: 12 | F33: =(D33+E33)/2 | G33: Flag outliers, trends & exceptions
A34: 26 | C34: Multi-model evaluation – GPT-4o vs GPT-4o-mini + 2 embedding models | D34: 6 | E34: 8 | F34: =(D34+E34)/2 | G34: Compare quality vs cost
A35: 27 | C35: Prompt logging (Azure Monitor / Log Analytics) | D35: 4 | E35: 6 | F35: =(D35+E35)/2 | G35: Full audit trail
A36: 28 | C36: Security controls – Key Vault, Entra ID managed identity | D36: 4 | E36: 8 | F36: =(D36+E36)/2 | G36: Least-privilege per-user controls
A37: 29 | C37: Rate limiting & user authorisation (10 POC users) | D37: 4 | E37: 6 | F37: =(D37+E37)/2 | G37: Azure AD group-based access
A38: 30 | C38: Conversation memory & session management | D38: 4 | E38: 6 | F38: =(D38+E38)/2 | G38: Short-term context retention
A40: Phase 4: Teams Bot Development (Copilot Studio) | D40: =SUM(D41:D47) | E40: =SUM(E41:E47) | F40: =(D40+E40)/2
A41: 31 | C41: Backend REST API (FastAPI) – bot orchestration layer | D41: 10 | E41: 14 | F41: =(D41+E41)/2 | G41: Query routing to AI agent
A42: 32 | C42: Azure AD / Entra SSO integration | D42: 4 | E42: 6 | F42: =(D42+E42)/2 | G42: Teams identity & service principal
A43: 33 | C43: Copilot Studio bot config & Teams channel publishing | D43: 6 | E43: 8 | F43: =(D43+E43)/2 | G43: Teams bot channel deployment
A44: 34 | C44: Adaptive cards / rich response formatting (all 3 use cases) | D44: 6 | E44: 8 | F44: =(D44+E44)/2 | G44: Structured output per use case
...

Sheet DevOps
A1: ECI AI PLATFORM BUILD – DEVOPS & INFRASTRUCTURE PROVISIONING
A3: # | B3: Task / Phase | C3: Sub-task | D3: Dev Low (hrs) | E3: Dev High (hrs) | F3: Avg (hrs) | G3: Comments
A4: Azure Environment Setup | D4: =SUM(D5:D16) | E4: =SUM(E5:E16) | F4: =(D4+E4)/2
A5: 1 | C5: Azure Resource Group, VNet & Subnets provisioning | D5: 2 | E5: 3 | F5: =(D5+E5)/2 | G5: Isolated network foundation
A6: 2 | C6: Private endpoints & Private Link config (all services) | D6: 8 | E6: 12 | F6: =(D6+E6)/2 | G6: All services off public internet
A7: 3 | C7: Azure AI Foundry workspace setup & model deployments | D7: 4 | E7: 6 | F7: =(D7+E7)/2 | G7: GPT-4o + GPT-4o-mini + embedding models
A8: 4 | C8: Azure AI Search instance (Standard S1) provisioning | D8: 2 | E8: 4 | F8: =(D8+E8)/2 | G8: Vector + keyword hybrid search
A9: 5 | C9: Azure App Service (P2V3) for bot backend | D9: 2 | E9: 3 | F9: =(D9+E9)/2 | G9: REST API hosting for FastAPI backend
A10: 6 | C10: Azure Key Vault & secrets configuration | D10: 2 | E10: 4 | F10: =(D10+E10)/2 | G10: API keys, credentials, managed identity
A11: 7 | C11: Azure Monitor + Log Analytics (90-day retention) | D11: 2 | E11: 3 | F11: =(D11+E11)/2 | G11: Prompt logging & observability
A12: 8 | C12: Azure SQL Database (Standard S3) provisioning | D12: 3 | E12: 4 | F12: =(D12+E12)/2 | G12: Structured metadata & audit log storage
A13: 9 | C13: Azure Blob Storage (LRS) for document staging | D13: 2 | E13: 3 | F13: =(D13+E13)/2 | G13: Temp staging & processed doc archive
A14: 10 | C14: SharePoint & REST API service principal configuration | D14: 3 | E14: 4 | F14: =(D14+E14)/2 | G14: Auth for all data source connectors
A15: 11 | C15: Entra ID / Azure AD app registrations | D15: 2 | E15: 3 | F15: =(D15+E15)/2 | G15: Auth for APIs & Teams bot
A16: 12 | C16: Azure Front Door / API Management (optional WAF layer) | D16: 3 | E16: 5 | F16: =(D16+E16)/2 | G16: Rate limiting, WAF rules
A18: Copilot Studio & Teams Integration | D18: =SUM(D19:D20) | E18: =SUM(E19:E20) | F18: =(D18+E18)/2
A19: 13 | C19: Copilot Studio environment provisioning & bot channel setup | D19: 3 | E19: 5 | F19: =(D19+E19)/2 | G19: Teams bot channel configuration
A20: 14 | C20: Teams admin consent & bot deployment to tenant | D20: 3 | E20: 5 | F20: =(D20+E20)/2 | G20: Admin approval required
A22: Security Baseline & Testing | D22: =SUM(D23:D25) | E22: =SUM(E23:E25) | F22: =(D22+E22)/2
A23: 15 | C23: NSG rules, Azure AD conditional access, Key Vault policies | D23: 4 | E23: 6 | F23: =(D23+E23)/2 | G23: Security hardening per scope
A24: 16 | C24: UAT staging environment deployment | D24: 2 | E24: 3 | F24: =(D24+E24)/2 | G24: Mirror of production
A25: 17 | C25: RBAC configuration – least-privilege roles per team member | D25: 2 | E25: 3 | F25: =(D25+E25)/2 | G25: PIM-based access review
A27: Meetings & Sync (10% of dev hours) | D27: =(D4+D18+D22)*0.1 | E27: =(E4+E18+E22)*0.1 | F27: =(D27+E27)/2 | G27: Standups, client syncs
A28: TOTAL DEVOPS HOURS | D28: =D4+D18+D22+D27 | E28: =E4+E18+E22+E27 | F28: =(D28+E28)/2 | G28: Average for budgeting

Sheet Architecture
A1: ECI AI PLATFORM BUILD – SOLUTION ARCHITECTURE
A3: Platform | B3: Microsoft Azure (existing subscription leveraged)
A4: AI Engine | B4: Azure OpenAI – GPT-4o (primary) + GPT-4o-mini (cost optimisation)
A5: Vector Store | B5: Azure AI Search Standard S1 – hybrid (vector + BM25)
A6: Embeddings | B6: text-embedding-3-large + text-embedding-ada-002
A7: Bot Channel | B7: Copilot Studio → Microsoft Teams
A8: Backend API | B8: FastAPI on Azure App Service P2V3
A9: Auth | B9: Azure AD / Entra ID – managed identity, SSO
A10: Data Sources | B10: SharePoint Online, REST APIs, Azure SQL, Azure Blob Storage
A11: Monitoring | B11: Azure Monitor + Log Analytics (90-day retention)
A12: Security | B12: Azure Key Vault, Private Endpoints, NSG, Conditional Access
D25: Use Case 1 – Document Q&A · Natural language question answering over enterprise documents (PDFs, Word, Excel) via Azure AI Search + GPT-4o RAG pipeline · Teams Adaptive Card trigger → Text + citation output
D26: Use Case 2 – Intelligent Report Summarisation · Automated multi-document synthesis & comparison with structured downloadable summary (Word/PDF) · Teams agent search → Formatted summary output
D27: Use Case 3 – Anomaly & Insight Detection · Structured data analysis flagging outliers, trends and exceptions across connected data sources · Teams notification → Dashboard-ready insight cards

Sheet Infra Cost
A1: ECI AI PLATFORM BUILD – INFRASTRUCTURE COST ESTIMATE
A2: # | B2: Service / Resource | C2: $/mo | D2: Pricing Model | E2: Notes / Assumptions
A3: AI Services — Azure AI Foundry / OpenAI
A4: 1 | B4: GPT-4o (Primary LLM — 85% of queries) | C4: 35 | D4: Pay-per-token | E4: ~750 queries/mo avg 1,200 input + 600 output tokens. GPT-4o: $2.50/$10 per 1M tokens. ~85% of queries.
A5: 2 | B5: GPT-4o-mini (Cost-optimised — 15% of queries) | C5: 5 | D5: Pay-per-token | E5: ~135 queries/mo comparison testing. GPT-4o-mini: $0.15/$0.60 per 1M tokens.
A6: Subtotal — AI Services | C6: =SUM(C4:C5)
A8: Vector Storage — Azure AI Search
A9: 3 | B9: Azure AI Search — Standard S1 (1 replica, 1 partition) | C9: 245 | D9: Fixed monthly | E9: S1 required for semantic ranker + hybrid search. ~$245/mo base. Supports all 3 use case indexes.
A10: Subtotal — Vector Storage | C10: =SUM(C9:C9)
A12: Compute — App Service & Functions
A13: 4 | B13: Azure App Service — P2V3 Linux (FastAPI backend / Teams bot) | C13: 80 | D13: Fixed monthly | E13: P2V3: 2 vCPU, 8 GB RAM. ~$80/mo. Hosts REST API for Copilot Studio bot.
A14: 5 | B14: Azure Functions — Consumption Plan (ingestion helper) | C14: 5 | D14: Pay-per-execution | E14: Used during SharePoint ingestion & delta sync. Near-zero ongoing cost.
A15: 6 | B15: Azure Blob Storage — LRS (document staging & archive) | C15: 10 | D15: Pay-per-GB | E15: ~20 GB document corpus + staging. $0.018/GB/mo.
A16: Subtotal — Compute | C16: =SUM(C13:C15)
A18: Database — Azure SQL
A19: 7 | B19: Azure SQL Database — Standard S3 (100 DTUs) | C19: 150 | D19: Fixed monthly | E19: S3 = 100 DTUs. Metadata queries, audit logs and cap rate lookup tables. Private endpoint included.
A20: Subtotal — Database / Azure SQL | C20: =SUM(C19:C19)
A22: Security & Identity
A23: 8 | B23: Azure Key Vault (secrets, API keys, managed identity) | C23: 10 | D23: Operations-based | E23: Standard tier. ~15K operations/mo. First 10K ops free, then $0.03/10K.
A24: 9 | B24: Entra ID / Azure AD (service principals, app registrations) | C24: 0 | D24: Included in M365 E3 | E24: No additional cost. 10 POC users on existing E3 licences.
A25: 10 | B25: Azure Front Door / API Management (WAF + rate limiting) | C25: 50 | D25: Fixed monthly | E25: Developer tier API Management. WAF policy + IP filtering.
A26: Subtotal — Security & Identity | C26: =SUM(C23:C25)
A28: Monitoring & Observability
A29: 11 | B29: Azure Monitor — Log Analytics Workspace | C29: 35 | D29: Per GB ingested | E29: Prompt logs for all interactions. ~3-5 GB/mo. $2.30/GB after 5 GB free tier.
A30: 12 | B30: Azure Monitor — Alerts & Dashboards | C30: 5 | D30: Per alert rule | E30: 10 alert rules for latency, error rate, ingestion status.
A31: Subtotal — Monitoring & Observability | C31: =SUM(C29:C30)
A33: Integration — Copilot Studio & Teams
A34: 13 | B34: Copilot Studio (Teams bot, Adaptive Cards – all 3 use cases) | C34: 200 | D34: Pay per message / tenant | E34: ~$200/tenant/mo standalone OR depends on M365 licence tier. Confirm with client.
A35: Subtotal — Integration | C35: =SUM(C34:C34)
A37: TOTAL ESTIMATED MONTHLY INFRASTRUCTURE COST | C37: =C6+C10+C16+C20+C26+C31+C35 | E37: Estimated monthly cost for POC environment. Excludes one-time setup costs and Copilot Studio (confirm licence with client).

Sheet Version History
A1: VERSION HISTORY
A3: Version | B3: Changes | C3: Date | D3: Author
A4: v1.0 | B4: Initial estimate based on ECI AI Platform scope document | C4: 2026-03-11 | D4: Prabhakar
