Workbook

Sheet Summary
A1: LENOX AI MVP BUILD – ESTIMATION SUMMARY
A3: Variables | F3: Team Allocation | L3: S.N. | Pre-Requisites (Client Responsibility)
A4: SNO | B4: Variables | C4: # | F4: SNO | G4: Role | H4: Allocation % | I4: Est. Days | L4: 1 | M4: Active Azure subscription with Contributor or Owner role at resource group level
A5: 1 | B5: FrontEnd | C5: No | F5: 1 | G5: Project Manager | H5: 33% | I5: =('AI Agent Dev- Backend'!F56+DevOps!F25)/7*0.33 -> 19.809429 | L5: 2 | M5: Microsoft 365 E3 (or higher) licenses for all service and user accounts
A6: 2 | B6: Backend | C6: Yes | F6: 2 | G6: AI Architect / Lead | H6: 50% | I6: =('AI Agent Dev- Backend'!F56+DevOps!F25)/7*0.5 -> 30.014286 | L6: 3 | M6: Copilot Studio license (standalone ~$200/tenant/mo or via M365 tier need to confirm with client)
A7: 3 | B7: DevOps | C7: Yes | F7: 3 | G7: AI Engineer | H7: 100% | I7: =('AI Agent Dev- Backend'!F56+DevOps!F25)/7*1 -> 60.028571 | L7: 4 | M7: Read-only SharePoint credentials and Graph API permissions for all source data
F8: 4 | G8: QA Engineer | H8: 50% | I8: =('AI Agent Dev- Backend'!F56+DevOps!F25)/7*0.5 -> 30.014286 | L8: 5 | M8: Microsoft Teams admin consent for custom Copilot Studio bot deployment
A9: Activities | F9: 5 | G9: DevOps | H9: 25% | I9: =('AI Agent Dev- Backend'!F56+DevOps!F25)/7*0.25 -> 15.007143 | L9: 6 | M9: Azure AD user accounts provisioned for 5 POC users
A10: SNO | B10: Activities | D10: DevTime (hrs) | L10: 7 | M10: Identification of key stakeholders for workshops and UAT sign-off
A11: 1 | B11: FrontEnd | D11: 0
A12: 2 | B12: Backend | D12: ='AI Agent Dev- Backend'!F56 -> 361.9 | F12: Monthly Infra Cost (Est.) | H12: ='Infra Cost'!C37 -> 497.75
A13: 3 | B13: DevOps | D13: =DevOps!F25 -> 58.3 | L13: S.N. | Out of Scope
L14: 1 | M14: Data ingestion from sources outside SharePoint (non-approved data)
B15: Component | C15: Days | D15: Weeks | L15: 2 | M15: Automated or scheduled pipeline ingestion — only one-time ingestion for POC is considered
B16: FrontEnd | C16: 0 | D16: 0 | L16: 3 | M16: Custom UI development for Teams or any other platform
B17: Backend | C17: ='AI Agent Dev- Backend'!F56/7 -> 51.7 | D17: ='AI Agent Dev- Backend'!F56/35 -> 10.34 | L17: 4 | M17: Building CI/CD pipelines or advanced deployment automation
B18: DevOps | C18: =DevOps!F25/7 -> 8.3285714 | D18: =DevOps!F25/35 -> 1.6657143 | L18: 5 | M18: PowerPoint (.pptx) files as data source types
A19: Project Duration | D19: ='AI Agent Dev- Backend'!F56/35 -> 10.34 | L19: 6 | M19: Long-term AI operations support or enterprise-wide AI platform standardization
L20: 7 | M20: Unstructured formats like mages, audio, and video not supported as data sources
A21: Project Duration including Leaves & Holiday | L21: 8 | M21: Non-standard or custom Excel formats , only the agreed standardized cap rate template is in scope. Any other file layout or formula structure is excluded.
B22: Leaves & Holiday | C22: 0 | D22: Weeks | L22: 9 | M22: Real-time market data , the AI will not pull live cap rate benchmarks, interest rates, or market comps from external sources.
C23: ='AI Agent Dev- Backend'!F56/35+C22 -> 10.34 | D23: Weeks | L23: 10 | M23: New board letter template design , ECI will use the template provided by Lenox. Creating or redesigning the template is out of scope.
A24: Note: With 2 AI Engineers, project can be completed within 6-7 weeks. | L24: 11 | M24: Data classification, labeling, or sensitivity tagging
L25: 12 | M25: Any new features or requests not mentioned in scope (change request process applies)
L27: S.N. | Assumptions
L28: 1 | M28: Source files are Excel, PDF, and Word only all other formats excluded
L29: 2 | M29: 50–100 historical files per use case will be provided within POC scope
L30: 3 | M30: AI response accuracy is estimated at 80–95% for structured queries. 100% accuracy is not guaranteed and is not a deliverable of this engagement.
L31: 4 | M31: AI responses are advisory in nature . all outputs (cap rate targets, letter revisions) must be reviewed and validated by Client before any business decision is made.
L32: 5 | M32: Model accuracy is dependent on the quality, consistency, and completeness of source files provided. Poor or inconsistent data will directly reduce response quality.
L33: 6 | M33: AI performance may vary across property types, markets, and deal structures not well-represented in historical training data.
L34: 7 | M34: The cap rate estimation Excel file format is assumed to be standardized and consistent across all files provided for ingestion. All files must follow the same template/structure.
L35: 8 | M35: If estimation Excel files vary in structure, layout, or formula logic across analysts or time periods, Client is responsible for normalizing these files prior to ingestion. ECI will not reformat or reconcile inconsistent files.
L36: 9 | M36: A single agreed-upon Excel template for cap rate calculations will be confirmed and locked during Discovery & Design. Any deviations from this template found will be out of scope
L37: 10 | M37: The AI will generate cap rate recommendations based on patterns in historical deal files . it will not replicate or replace the Excel formula engine. The output is a recommendation, not a guaranteed calculation.
L38: 11 | M38: The number of input variables for the estimation use case (e.g., NOI, asking price, location tier, asset class) will be defined and locked during prompt engineering design(Discovery). Additional variables requested after design sign-off are a change request.
L39: 12 | M39: A fixed, approved board letter template will be provided by Client during Discovery & Design and will serve as the style reference for the AI. This template will not change during the engagement.
... L50: 23 | M50: Client will assign UAT resource(s) and respond to ECI queries within 24–48 hours
L52: S.N. | Risks
L53: 1 | M53: SharePoint API restrictions: Permission or access issues may add significant effort validate in Discovery
...

Sheet AI Agent Dev- Backend
A1: LENOX AI MVP BUILD – AI AGENT DEVELOPMENT & INTEGRATION
A3: # | B3: Task / Phase | C3: Sub-task | D3: Dev Low (hrs) | E3: Dev High (hrs) | F3: Avg (hrs) | G3: Comments
A4: Phase 1: Discovery & Design | D4: =SUM(D5:D11) -> 56 | E4: =SUM(E5:E11) -> 78 | F4: =(D4+E4)/2 -> 67
A5: 1 | C5: Project kickoff, scope confirmation & stakeholder alignment | D5: 8 | E5: 10 | F5: =(D5+E5)/2 -> 9 | G5: Requirements review with stakeholders & delegates
A6: 2 | C6: SharePoint data source review – Excel, Word, PDF (schema, auth, payload) | D6: 8 | E6: 12 | F6: =(D6+E6)/2 -> 10 | G6: Validate file structures for each source
A7: 3 | C7: 50-100 file sample review – estimation & board letters | D7: 8 | E7: 12 | F7: =(D7+E7)/2 -> 10 | G7: Validate content quality & metadata structure
A8: 4 | C8: Architecture finalization and sign-off | D8: 4 | E8: 6 | F8: =(D8+E8)/2 -> 5 | G8: Private endpoint & Azure landing zone review
A9: 5 | C9: Creating necessary Documents | D9: 12 | E9: 16 | F9: =(D9+E9)/2 -> 14 | G9: Technical design & architecture docs
A10: 6 | C10: Prompt engineering design for both use cases | D10: 8 | E10: 12 | F10: =(D10+E10)/2 -> 10 | G10: Cap rate estimation + board letter review prompts
A11: 7 | C11: KPI metric & threshold definition | D11: 8 | E11: 10 | F11: =(D11+E11)/2 -> 9 | G11: Accuracy, response time, relevance benchmarks
A13: Phase 2: Data Ingestion & SharePoint Processing | D13: =SUM(D14:D20) -> 74 | E13: =SUM(E14:E20) -> 104 | F13: =(D13+E13)/2 -> 89
A14: 8 | C14: SharePoint connector setup (OAuth, Graph API, read permissions) | D14: 6 | E14: 10 | F14: =(D14+E14)/2 -> 8 | G14: One-time ingestion pipeline from SharePoint
A15: 9 | C15: Excel file parsing & metadata tagging (Use Case 1 – Estimation) | D15: 10 | E15: 14 | F15: =(D15+E15)/2 -> 12 | G15: Cap rate & underwriting Excel files
A16: 10 | C16: Word/PDF file parsing & metadata tagging (Use Case 2 – Board Letter) | D16: 10 | E16: 14 | F16: =(D16+E16)/2 -> 12 | G16: Historical quarterly board letters
A17: 11 | C17: Intelligent text chunking & metadata strategy (cross use case) | D17: 6 | E17: 10 | F17: =(D17+E17)/2 -> 8 | G17: Chunk sizing for financial documents
A18: 12 | C18: Azure OpenAI Embedding integration (2 embedding models) | D18: 14 | E18: 18 | F18: =(D18+E18)/2 -> 16 | G18: text-embedding-3-large + ada-002
A19: 13 | C19: One-time embedding generation for all source files | D19: 12 | E19: 16 | F19: =(D19+E19)/2 -> 14
A20: 14 | C20: Azure AI Search schema design + hybrid search config | D20: 16 | E20: 22 | F20: =(D20+E20)/2 -> 19
A22: Phase 3: AI Agent Development | D22: =SUM(D23:D32) -> 68 | E22: =SUM(E23:E32) -> 98 | F22: =(D22+E22)/2 -> 83
A23: 17 | C23: Use Case 1: Estimation/underwriting – prompt engineering & RAG pipeline | D23: 10 | E23: 14 | F23: =(D23+E23)/2 -> 12 | G23: Cap rate analysis & scenario prompting
A24: 18 | C24: Use Case 1: Excel data extraction & cap rate calculation logic | D24: 10 | E24: 14 | F24: =(D24+E24)/2 -> 12 | G24: Parse NOI, property value, scenario inputs
A25: 19 | C25: Use Case 1: Adaptive Card trigger & response formatting (Teams) | D25: 6 | E25: 8 | F25: =(D25+E25)/2 -> 7 | G25: Trigger via Teams Adaptive Card; output as text
A26: 20 | C26: Use Case 2: Board letter review – prompt engineering & RAG pipeline | D26: 10 | E26: 14 | F26: =(D26+E26)/2 -> 12 | G26: Draft comparison against historical final letters
A27: 21 | C27: Use Case 2: Word/PDF retrieval & revision recommendation logic | D27: 8 | E27: 12 | F27: =(D27+E27)/2 -> 10 | G27: Semantic search over prior approved drafts
A28: 22 | C28: Use Case 2: Draft analysis & tone/style recommendation output | D28: 6 | E28: 8 | F28: =(D28+E28)/2 -> 7 | G28: Structured revision suggestions
A29: 23 | C29: Multi-model evaluation – compare 2 base + 2 embedding models | D29: 6 | E29: 8 | F29: =(D29+E29)/2 -> 7
A30: 24 | C30: Prompt logging implementation (Azure Monitor / Log Analytics) | D30: 4 | E30: 6 | F30: =(D30+E30)/2 -> 5
A31: 25 | C31: Security controls: Key Vault secrets, Entra ID managed identity | D31: 4 | E31: 8 | F31: =(D31+E31)/2 -> 6 | G31: Per-user throttling & managed identity
A32: 26 | C32: Rate limiting & user authorization (5 POC users) | D32: 4 | E32: 6 | F32: =(D32+E32)/2 -> 5 | G32: Azure AD validation
A34: Phase 4: Teams Bot Development (Copilot Studio) | D34: =SUM(D35:D39) -> 28 | E34: =SUM(E35:E39) -> 42 | F34: =(D34+E34)/2 -> 35
A35: 28 | C35: Backend REST API development (FastAPI) – bot orchestration | D35: 10 | E35: 14 | F35: =(D35+E35)/2 -> 12 | G35: Query routing to AI agent
A36: 29 | C36: Azure AD / Entra authentication & SSO integration | D36: 4 | E36: 6 | F36: =(D36+E36)/2 -> 5 | G36: Teams identity & service principal
A37: 30 | C37: Copilot Studio bot config & Teams channel publishing | D37: 6 | E37: 8 | F37: =(D37+E37)/2 -> 7 | G37: Teams bot channel deployment
A38: 31 | C38: Adaptive cards / rich response formatting (both use cases) | D38: 4 | E38: 6 | F38: =(D38+E38)/2 -> 5 | G38: Structured output for Estimation & Board Letter
A39: 32 | C39: End-to-end conversation flow testing | D39: 4 | E39: 8 | F39: =(D39+E39)/2 -> 6 | G39: Validate both use case flows in Teams
A41: Phase 5: Testing & UAT | D41: =SUM(D42:D48) -> 36 | E41: =SUM(E42:E48) -> 54 | F41: =(D41+E41)/2 -> 45
A42: 33 | C42: Unit testing – all agent components | D42: 6 | E42: 10 | F42: =(D42+E42)/2 -> 8 | G42: Function-level tests for both use cases
A43: 34 | C43: Integration testing – end-to-end workflow (both use cases) | D43: 6 | E43: 10 | F43: =(D43+E43)/2 -> 8 | G43: SharePoint → Agent → Teams validation
A44: 35 | C44: Prompt engineering tuning (both use cases) | D44: 8 | E44: 12 | F44: =(D44+E44)/2 -> 10 | G44: Optimize against KPI thresholds
A45: 37 | C45: Performance testing – response time target <10s | D45: 4 | E45: 6 | F45: =(D45+E45)/2 -> 5 | G45: 5 concurrent users simulation
...

Sheet DevOps
A1: LENOX AI MVP BUILD – DEVOPS & INFRASTRUCTURE PROVISIONING
A3: # | B3: Task / Phase | C3: Sub-task | D3: Dev Low (hrs) | E3: Dev High (hrs) | F3: Avg (hrs) | G3: Comments
A4: Azure Environment Setup | D4: =SUM(D5:D14) -> 30 | E4: =SUM(E5:E14) -> 46 | F4: =(D4+E4)/2 -> 38
A5: 1 | C5: Azure Resource Group, VNet & Subnets provisioning | D5: 2 | E5: 3 | F5: =(D5+E5)/2 -> 2.5 | G5: Isolated network foundation
A6: 2 | C6: Private endpoints & Private Link config (all services) | D6: 8 | E6: 12 | F6: =(D6+E6)/2 -> 10 | G6: Mandatory per scope – all services off public internet
A7: 3 | C7: Azure AI Foundry workspace setup & model deployments | D7: 4 | E7: 6 | F7: =(D7+E7)/2 -> 5 | G7: GPT-5 + GPT-4o-mini + embedding model deployments
A8: 4 | C8: Azure AI Search instance (Standard S1) provisioning | D8: 2 | E8: 4 | F8: =(D8+E8)/2 -> 3 | G8: Vector + keyword hybrid search
A9: 5 | C9: Azure App Service (P1V2) for bot backend | D9: 2 | E9: 3 | F9: =(D9+E9)/2 -> 2.5 | G9: REST API hosting for FastAPI backend
A10: 6 | C10: Azure Key Vault & secrets configuration | D10: 2 | E10: 4 | F10: =(D10+E10)/2 -> 3 | G10: API keys, credentials, managed identity
A11: 7 | C11: Azure Monitor + Log Analytics (30-day retention) | D11: 2 | E11: 3 | F11: =(D11+E11)/2 -> 2.5 | G11: Prompt logging & observability
A12: 8 | C12: Azure SQL Database (Standard S2) provisioning | D12: 3 | E12: 4 | F12: =(D12+E12)/2 -> 3.5 | G12: Structured metadata storage
A13: 9 | C13: SharePoint service principal & Graph API config | D13: 3 | E13: 4 | F13: =(D13+E13)/2 -> 3.5 | G13: Authentication for SharePoint data ingestion
A14: 10 | C14: Entra ID / Azure AD app registrations | D14: 2 | E14: 3 | F14: =(D14+E14)/2 -> 2.5 | G14: Auth for APIs & Teams bot
A16: Copilot Studio & Teams Integration | D16: =SUM(D17:D18) -> 6 | E16: =SUM(E17:E18) -> 10 | F16: =(D16+E16)/2 -> 8
A17: 11 | C17: Copilot Studio environment provisioning & bot channel setup | D17: 3 | E17: 5 | F17: =(D17+E17)/2 -> 4 | G17: Teams bot channel configuration
A18: 12 | C18: Teams admin consent & bot deployment to tenant | D18: 3 | E18: 5 | F18: =(D18+E18)/2 -> 4 | G18: Admin approval required
A20: Security Baseline & Testing | D20: =SUM(D21:D22) -> 6 | E20: =SUM(E21:E22) -> 8 | F20: =(D20+E20)/2 -> 7
A21: 13 | C21: NSG rules, Azure AD conditional access, Key Vault policies | D21: 4 | E21: 6 | F21: =(D21+E21)/2 -> 5 | G21: Security hardening per scope
A22: 14 | C22: UAT staging environment deployment | D22: 2 | E22: 2 | F22: =(D22+E22)/2 -> 2 | G22: Mirror of production
A24: Meetings & Sync (10% of dev hours) | D24: =(D4+D16+D20)*0.1 -> 4.2 | E24: =(E4+E16+E20)*0.1 -> 6.4 | F24: =(D24+E24)/2 -> 5.3 | G24: Standups, client syncs
A25: TOTAL DEVOPS HOURS | D25: =D4+D16+D20+D24 -> 46.2 | E25: =E4+E16+E20+E24 -> 70.4 | F25: =(D25+E25)/2 -> 58.3 | G25: Average for budgeting

Sheet Architecture
D25: Use Case 1 – Estimation & Underwriting (Cap Rate Analysis) · Adaptive Card trigger → Text output
D26: Use Case 2 – Quarterly Board Letter Review & Revision · Teams agent search → Text output

Sheet Infra Cost
A1: LENOX AI MVP – INFRASTRUCTURE COST ESTIMATE
A2: # | B2: Service / Resource | C2: $/mo | D2: Pricing Model | E2: Notes / Assumptions
A3: AI Services — Azure AI Foundry / OpenAI
A4: 1 | B4: GPT-4o (Primary LLM — 90% of queries) | C4: 15 | D4: Pay-per-token | E4: 375 queries/mo avg 1,000 input + 500 output tokens. GPT-4o: $2.50/$10 per 1M tokens. ~90% of queries.
A5: 2 | B5: GPT-4o-mini (Secondary LLM — 10% of queries) | C5: 8 | D5: Pay-per-token | E5: ~38 queries/mo comparison testing. GPT-4o-mini: $0.15/$0.60 per 1M tokens.
A6: Subtotal — AI Services | C6: =SUM(C4:C5) -> 23
A8: Vector Storage — Azure AI Search
A9: 3 | B9: Azure AI Search — Standard S1 (1 replica, 1 partition) | C9: 245 | D9: Fixed monthly | E9: S1 required for semantic ranker + hybrid search. ~$245/mo base. Supports both use case indexes.
A10: Subtotal — Vector Storage | C10: =C9 -> 245
A12: Compute — App Service & Functions
A13: 4 | B13: Azure App Service — P1V2 Linux (FastAPI backend / Teams bot) | C13: 54.75 | D13: Fixed monthly | E13: P1V2: 1 vCPU, 3.5 GB RAM. ~$54.75/mo. Hosts REST API for Copilot Studio bot.
A14: 5 | B14: Azure Functions — Consumption Plan (ingestion helper, one-time) | C14: 5 | D14: Pay-per-execution | E14: Used only during initial SharePoint ingestion. Near-zero ongoing cost after setup.
A15: 6 | B15: Azure Blob Storage — LRS (temp staging for file processing) | C15: 5 | D15: Pay-per-GB | E15: 5 GB one-time upload staging. $0.018/GB/mo after ingestion (~$0.09/mo ongoing).
A16: Subtotal — Compute | C16: =SUM(C13:C15) -> 64.75
A18: Database — Azure SQL
A19: 7 | B19: Azure SQL Database — Standard S2 (50 DTUs) | C19: 75 | D19: Fixed monthly | E19: S2 = 50 DTUs. Handles structured metadata queries and cap rate lookup tables. Private endpoint included.
A20: Subtotal — Database / Azure SQL | C20: =C19 -> 75
A22: Security & Identity
A23: 8 | B23: Azure Key Vault (secrets, API keys, managed identity) | C23: 10 | D23: Operations-based | E23: Standard tier. ~10K operations/mo. First 10K ops free, then $0.03/10K.
A24: 9 | B24: Entra ID / Azure AD (service principals, app registrations) | C24: $ – | D24: Included in M365 E3 | E24: No additional cost. 5 POC users on existing E3 licences.
A25: Subtotal — Security & Identity | C25: =C23 -> 10
A27: Monitoring & Observability
A28: 10 | B28: Azure Monitor — Log Analytics Workspace | C28: 25 | D28: Per GB ingested | E28: Prompt logs for all interactions. ~1-2 GB/mo. $2.30/GB after 5 GB free tier.
A29: 11 | B29: Azure Monitor — Alerts & Dashboards | C29: 5 | D29: Per alert rule | E29: MVP: demonstrate logging active during presentation. First 10 alert rules free.
A30: Subtotal — Monitoring & Observability | C30: =SUM(C28:C29) -> 30
A32: Integration — Copilot Studio & Teams
A33: 12 | B33: Copilot Studio (Teams bot, Adaptive Cards – both use cases) | C33: 50 | D33: Pay per message | E33: ~$200/tenant/mo standalone OR Depends on M365 licence tier. Confirm with client.
A34: Subtotal — Integration | C34: =C33 -> 50
A37: TOTAL ESTIMATED MONTHLY INFRASTRUCTURE COST | C37: =C6+C10+C16+C20+C25+C30+C34 -> 497.75 | E37: Estimated monthly cost for POC environment. Excludes one-time setup costs.

Sheet Version History
A1: VERSION HISTORY
A3: Version | B3: Changes | C3: Date | D3: Author
A4: v1.0 | B4: Initial estimate based on Lenox AI MVP scope document | C4: 2026-03-09 | D4: Prabhakar
A5: v1.1 | B5: Updated models to GPT-5 and GPT-4o-mini; full formula rebuild; Summary governance sections added | C5: 2026-03-10 | D5: Prabhakar
